[2023-02-17T23:37:41.430+0000] {taskinstance.py:1083} INFO - Dependencies all met for <TaskInstance: booking_ingestion.load_data manual__2023-02-17T23:37:39.405925+00:00 [queued]>
[2023-02-17T23:37:41.437+0000] {taskinstance.py:1083} INFO - Dependencies all met for <TaskInstance: booking_ingestion.load_data manual__2023-02-17T23:37:39.405925+00:00 [queued]>
[2023-02-17T23:37:41.438+0000] {taskinstance.py:1279} INFO - 
--------------------------------------------------------------------------------
[2023-02-17T23:37:41.440+0000] {taskinstance.py:1280} INFO - Starting attempt 1 of 1
[2023-02-17T23:37:41.440+0000] {taskinstance.py:1281} INFO - 
--------------------------------------------------------------------------------
[2023-02-17T23:37:41.449+0000] {taskinstance.py:1300} INFO - Executing <Task(PythonOperator): load_data> on 2023-02-17 23:37:39.405925+00:00
[2023-02-17T23:37:41.458+0000] {standard_task_runner.py:55} INFO - Started process 140 to run task
[2023-02-17T23:37:41.462+0000] {standard_task_runner.py:82} INFO - Running: ['***', 'tasks', 'run', 'booking_ingestion', 'load_data', 'manual__2023-02-17T23:37:39.405925+00:00', '--job-id', '114', '--raw', '--subdir', 'DAGS_FOLDER/data_ingestion_dag/main.py', '--cfg-path', '/tmp/tmpsds55gpa']
[2023-02-17T23:37:41.464+0000] {standard_task_runner.py:83} INFO - Job 114: Subtask load_data
[2023-02-17T23:37:41.526+0000] {task_command.py:388} INFO - Running <TaskInstance: booking_ingestion.load_data manual__2023-02-17T23:37:39.405925+00:00 [running]> on host f01ad4775be8
[2023-02-17T23:37:41.579+0000] {taskinstance.py:1509} INFO - Exporting the following env vars:
AIRFLOW_CTX_DAG_OWNER=***
AIRFLOW_CTX_DAG_ID=booking_ingestion
AIRFLOW_CTX_TASK_ID=load_data
AIRFLOW_CTX_EXECUTION_DATE=2023-02-17T23:37:39.405925+00:00
AIRFLOW_CTX_TRY_NUMBER=1
AIRFLOW_CTX_DAG_RUN_ID=manual__2023-02-17T23:37:39.405925+00:00
[2023-02-17T23:37:41.583+0000] {taskinstance.py:1768} ERROR - Task failed with exception
Traceback (most recent call last):
  File "/home/airflow/.local/lib/python3.7/site-packages/airflow/operators/python.py", line 175, in execute
    return_value = self.execute_callable()
  File "/home/airflow/.local/lib/python3.7/site-packages/airflow/operators/python.py", line 192, in execute_callable
    return self.python_callable(*self.op_args, **self.op_kwargs)
  File "/opt/airflow/dags/data_ingestion_dag/main.py", line 47, in load_data
    conn = psycopg2.connect("/usr/local/airflow/db/datascience.db")
  File "/home/airflow/.local/lib/python3.7/site-packages/psycopg2/__init__.py", line 121, in connect
    dsn = _ext.make_dsn(dsn, **kwargs)
  File "/home/airflow/.local/lib/python3.7/site-packages/psycopg2/extensions.py", line 145, in make_dsn
    parse_dsn(dsn)
psycopg2.ProgrammingError: invalid dsn: missing "=" after "/usr/local/***/db/datascience.db" in connection info string

[2023-02-17T23:37:41.593+0000] {taskinstance.py:1323} INFO - Marking task as FAILED. dag_id=booking_ingestion, task_id=load_data, execution_date=20230217T233739, start_date=20230217T233741, end_date=20230217T233741
[2023-02-17T23:37:41.602+0000] {standard_task_runner.py:105} ERROR - Failed to execute job 114 for task load_data (invalid dsn: missing "=" after "/usr/local/***/db/datascience.db" in connection info string
; 140)
[2023-02-17T23:37:41.635+0000] {local_task_job.py:208} INFO - Task exited with return code 1
[2023-02-17T23:37:41.660+0000] {taskinstance.py:2578} INFO - 0 downstream tasks scheduled from follow-on schedule check
