[2023-02-17T23:22:13.549+0000] {taskinstance.py:1083} INFO - Dependencies all met for <TaskInstance: booking_ingestion.load_data scheduled__2023-02-16T23:22:06.849420+00:00 [queued]>
[2023-02-17T23:22:13.559+0000] {taskinstance.py:1083} INFO - Dependencies all met for <TaskInstance: booking_ingestion.load_data scheduled__2023-02-16T23:22:06.849420+00:00 [queued]>
[2023-02-17T23:22:13.563+0000] {taskinstance.py:1279} INFO - 
--------------------------------------------------------------------------------
[2023-02-17T23:22:13.564+0000] {taskinstance.py:1280} INFO - Starting attempt 1 of 1
[2023-02-17T23:22:13.566+0000] {taskinstance.py:1281} INFO - 
--------------------------------------------------------------------------------
[2023-02-17T23:22:13.577+0000] {taskinstance.py:1300} INFO - Executing <Task(PythonOperator): load_data> on 2023-02-16 23:22:06.849420+00:00
[2023-02-17T23:22:13.584+0000] {standard_task_runner.py:55} INFO - Started process 93 to run task
[2023-02-17T23:22:13.588+0000] {standard_task_runner.py:82} INFO - Running: ['***', 'tasks', 'run', 'booking_ingestion', 'load_data', 'scheduled__2023-02-16T23:22:06.849420+00:00', '--job-id', '44', '--raw', '--subdir', 'DAGS_FOLDER/data_ingestion_dag/main.py', '--cfg-path', '/tmp/tmplo1nka7f']
[2023-02-17T23:22:13.589+0000] {standard_task_runner.py:83} INFO - Job 44: Subtask load_data
[2023-02-17T23:22:13.664+0000] {task_command.py:388} INFO - Running <TaskInstance: booking_ingestion.load_data scheduled__2023-02-16T23:22:06.849420+00:00 [running]> on host 669eb8e0865e
[2023-02-17T23:22:13.720+0000] {taskinstance.py:1509} INFO - Exporting the following env vars:
AIRFLOW_CTX_DAG_OWNER=***
AIRFLOW_CTX_DAG_ID=booking_ingestion
AIRFLOW_CTX_TASK_ID=load_data
AIRFLOW_CTX_EXECUTION_DATE=2023-02-16T23:22:06.849420+00:00
AIRFLOW_CTX_TRY_NUMBER=1
AIRFLOW_CTX_DAG_RUN_ID=scheduled__2023-02-16T23:22:06.849420+00:00
[2023-02-17T23:22:13.725+0000] {taskinstance.py:1768} ERROR - Task failed with exception
Traceback (most recent call last):
  File "/home/airflow/.local/lib/python3.7/site-packages/airflow/operators/python.py", line 175, in execute
    return_value = self.execute_callable()
  File "/home/airflow/.local/lib/python3.7/site-packages/airflow/operators/python.py", line 192, in execute_callable
    return self.python_callable(*self.op_args, **self.op_kwargs)
  File "/opt/airflow/dags/data_ingestion_dag/main.py", line 46, in load_data
    conn = sqlite3.connect("/usr/local/airflow/db/datascience.db")
sqlite3.OperationalError: unable to open database file
[2023-02-17T23:22:13.737+0000] {taskinstance.py:1323} INFO - Marking task as FAILED. dag_id=booking_ingestion, task_id=load_data, execution_date=20230216T232206, start_date=20230217T232213, end_date=20230217T232213
[2023-02-17T23:22:13.747+0000] {standard_task_runner.py:105} ERROR - Failed to execute job 44 for task load_data (unable to open database file; 93)
[2023-02-17T23:22:13.803+0000] {local_task_job.py:208} INFO - Task exited with return code 1
[2023-02-17T23:22:13.820+0000] {taskinstance.py:2578} INFO - 0 downstream tasks scheduled from follow-on schedule check
