[2023-02-18T01:01:24.500+0000] {taskinstance.py:1083} INFO - Dependencies all met for <TaskInstance: booking_ingestion.load_data manual__2023-02-18T01:01:21.281011+00:00 [queued]>
[2023-02-18T01:01:24.508+0000] {taskinstance.py:1083} INFO - Dependencies all met for <TaskInstance: booking_ingestion.load_data manual__2023-02-18T01:01:21.281011+00:00 [queued]>
[2023-02-18T01:01:24.510+0000] {taskinstance.py:1279} INFO - 
--------------------------------------------------------------------------------
[2023-02-18T01:01:24.511+0000] {taskinstance.py:1280} INFO - Starting attempt 1 of 1
[2023-02-18T01:01:24.512+0000] {taskinstance.py:1281} INFO - 
--------------------------------------------------------------------------------
[2023-02-18T01:01:24.522+0000] {taskinstance.py:1300} INFO - Executing <Task(PythonOperator): load_data> on 2023-02-18 01:01:21.281011+00:00
[2023-02-18T01:01:24.528+0000] {standard_task_runner.py:55} INFO - Started process 1552 to run task
[2023-02-18T01:01:24.532+0000] {standard_task_runner.py:82} INFO - Running: ['***', 'tasks', 'run', 'booking_ingestion', 'load_data', 'manual__2023-02-18T01:01:21.281011+00:00', '--job-id', '280', '--raw', '--subdir', 'DAGS_FOLDER/data_ingestion_dag/main.py', '--cfg-path', '/tmp/tmpstm58l4u']
[2023-02-18T01:01:24.533+0000] {standard_task_runner.py:83} INFO - Job 280: Subtask load_data
[2023-02-18T01:01:24.596+0000] {task_command.py:388} INFO - Running <TaskInstance: booking_ingestion.load_data manual__2023-02-18T01:01:21.281011+00:00 [running]> on host d92f32803fb9
[2023-02-18T01:01:24.648+0000] {taskinstance.py:1509} INFO - Exporting the following env vars:
AIRFLOW_CTX_DAG_OWNER=***
AIRFLOW_CTX_DAG_ID=booking_ingestion
AIRFLOW_CTX_TASK_ID=load_data
AIRFLOW_CTX_EXECUTION_DATE=2023-02-18T01:01:21.281011+00:00
AIRFLOW_CTX_TRY_NUMBER=1
AIRFLOW_CTX_DAG_RUN_ID=manual__2023-02-18T01:01:21.281011+00:00
[2023-02-18T01:01:24.670+0000] {base.py:73} INFO - Using connection ID 'postgres_db' for task execution.
[2023-02-18T01:01:24.682+0000] {taskinstance.py:1768} ERROR - Task failed with exception
Traceback (most recent call last):
  File "/home/airflow/.local/lib/python3.7/site-packages/airflow/operators/python.py", line 175, in execute
    return_value = self.execute_callable()
  File "/home/airflow/.local/lib/python3.7/site-packages/airflow/operators/python.py", line 192, in execute_callable
    return self.python_callable(*self.op_args, **self.op_kwargs)
  File "/opt/airflow/dags/data_ingestion_dag/main.py", line 52, in load_data
    postgres_sql_upload.insert_rows('booking_record', records)
  File "/home/airflow/.local/lib/python3.7/site-packages/airflow/providers/common/sql/hooks/sql.py", line 453, in insert_rows
    with closing(self.get_conn()) as conn:
  File "/home/airflow/.local/lib/python3.7/site-packages/airflow/providers/postgres/hooks/postgres.py", line 144, in get_conn
    self.conn = psycopg2.connect(**conn_args)
  File "/home/airflow/.local/lib/python3.7/site-packages/psycopg2/__init__.py", line 122, in connect
    conn = _connect(dsn, connection_factory=connection_factory, **kwasync)
psycopg2.OperationalError: FATAL:  database "d" does not exist

[2023-02-18T01:01:24.695+0000] {taskinstance.py:1323} INFO - Marking task as FAILED. dag_id=booking_ingestion, task_id=load_data, execution_date=20230218T010121, start_date=20230218T010124, end_date=20230218T010124
[2023-02-18T01:01:24.706+0000] {standard_task_runner.py:105} ERROR - Failed to execute job 280 for task load_data (FATAL:  database "d" does not exist
; 1552)
[2023-02-18T01:01:24.747+0000] {local_task_job.py:208} INFO - Task exited with return code 1
[2023-02-18T01:01:24.765+0000] {taskinstance.py:2578} INFO - 0 downstream tasks scheduled from follow-on schedule check
