[2023-02-17T23:47:45.133+0000] {taskinstance.py:1083} INFO - Dependencies all met for <TaskInstance: booking_ingestion.load_data manual__2023-02-17T23:47:42.580266+00:00 [queued]>
[2023-02-17T23:47:45.140+0000] {taskinstance.py:1083} INFO - Dependencies all met for <TaskInstance: booking_ingestion.load_data manual__2023-02-17T23:47:42.580266+00:00 [queued]>
[2023-02-17T23:47:45.141+0000] {taskinstance.py:1279} INFO - 
--------------------------------------------------------------------------------
[2023-02-17T23:47:45.141+0000] {taskinstance.py:1280} INFO - Starting attempt 1 of 1
[2023-02-17T23:47:45.143+0000] {taskinstance.py:1281} INFO - 
--------------------------------------------------------------------------------
[2023-02-17T23:47:45.152+0000] {taskinstance.py:1300} INFO - Executing <Task(PythonOperator): load_data> on 2023-02-17 23:47:42.580266+00:00
[2023-02-17T23:47:45.158+0000] {standard_task_runner.py:55} INFO - Started process 90 to run task
[2023-02-17T23:47:45.162+0000] {standard_task_runner.py:82} INFO - Running: ['***', 'tasks', 'run', 'booking_ingestion', 'load_data', 'manual__2023-02-17T23:47:42.580266+00:00', '--job-id', '151', '--raw', '--subdir', 'DAGS_FOLDER/data_ingestion_dag/main.py', '--cfg-path', '/tmp/tmp8q0uak8j']
[2023-02-17T23:47:45.164+0000] {standard_task_runner.py:83} INFO - Job 151: Subtask load_data
[2023-02-17T23:47:45.227+0000] {task_command.py:388} INFO - Running <TaskInstance: booking_ingestion.load_data manual__2023-02-17T23:47:42.580266+00:00 [running]> on host f01ad4775be8
[2023-02-17T23:47:45.309+0000] {taskinstance.py:1509} INFO - Exporting the following env vars:
AIRFLOW_CTX_DAG_OWNER=***
AIRFLOW_CTX_DAG_ID=booking_ingestion
AIRFLOW_CTX_TASK_ID=load_data
AIRFLOW_CTX_EXECUTION_DATE=2023-02-17T23:47:42.580266+00:00
AIRFLOW_CTX_TRY_NUMBER=1
AIRFLOW_CTX_DAG_RUN_ID=manual__2023-02-17T23:47:42.580266+00:00
[2023-02-17T23:47:45.313+0000] {taskinstance.py:1768} ERROR - Task failed with exception
Traceback (most recent call last):
  File "/home/airflow/.local/lib/python3.7/site-packages/airflow/operators/python.py", line 175, in execute
    return_value = self.execute_callable()
  File "/home/airflow/.local/lib/python3.7/site-packages/airflow/operators/python.py", line 192, in execute_callable
    return self.python_callable(*self.op_args, **self.op_kwargs)
  File "/opt/airflow/dags/data_ingestion_dag/main.py", line 47, in load_data
    conn = psycopg2.connect("dbname=airflow user=airflow password=airflow")
  File "/home/airflow/.local/lib/python3.7/site-packages/psycopg2/__init__.py", line 122, in connect
    conn = _connect(dsn, connection_factory=connection_factory, **kwasync)
psycopg2.OperationalError: could not connect to server: No such file or directory
	Is the server running locally and accepting
	connections on Unix domain socket "/var/run/postgresql/.s.PGSQL.5432"?

[2023-02-17T23:47:45.324+0000] {taskinstance.py:1323} INFO - Marking task as FAILED. dag_id=booking_ingestion, task_id=load_data, execution_date=20230217T234742, start_date=20230217T234745, end_date=20230217T234745
[2023-02-17T23:47:45.333+0000] {standard_task_runner.py:105} ERROR - Failed to execute job 151 for task load_data (could not connect to server: No such file or directory
	Is the server running locally and accepting
	connections on Unix domain socket "/var/run/postgresql/.s.PGSQL.5432"?
; 90)
[2023-02-17T23:47:45.378+0000] {local_task_job.py:208} INFO - Task exited with return code 1
[2023-02-17T23:47:45.394+0000] {taskinstance.py:2578} INFO - 0 downstream tasks scheduled from follow-on schedule check
