[2023-02-17T23:25:33.812+0000] {taskinstance.py:1083} INFO - Dependencies all met for <TaskInstance: booking_ingestion.load_data manual__2023-02-17T23:25:30.795016+00:00 [queued]>
[2023-02-17T23:25:33.818+0000] {taskinstance.py:1083} INFO - Dependencies all met for <TaskInstance: booking_ingestion.load_data manual__2023-02-17T23:25:30.795016+00:00 [queued]>
[2023-02-17T23:25:33.820+0000] {taskinstance.py:1279} INFO - 
--------------------------------------------------------------------------------
[2023-02-17T23:25:33.821+0000] {taskinstance.py:1280} INFO - Starting attempt 1 of 1
[2023-02-17T23:25:33.822+0000] {taskinstance.py:1281} INFO - 
--------------------------------------------------------------------------------
[2023-02-17T23:25:33.832+0000] {taskinstance.py:1300} INFO - Executing <Task(PythonOperator): load_data> on 2023-02-17 23:25:30.795016+00:00
[2023-02-17T23:25:33.838+0000] {standard_task_runner.py:55} INFO - Started process 82 to run task
[2023-02-17T23:25:33.842+0000] {standard_task_runner.py:82} INFO - Running: ['***', 'tasks', 'run', 'booking_ingestion', 'load_data', 'manual__2023-02-17T23:25:30.795016+00:00', '--job-id', '77', '--raw', '--subdir', 'DAGS_FOLDER/data_ingestion_dag/main.py', '--cfg-path', '/tmp/tmpx2f4p3ah']
[2023-02-17T23:25:33.844+0000] {standard_task_runner.py:83} INFO - Job 77: Subtask load_data
[2023-02-17T23:25:33.910+0000] {task_command.py:388} INFO - Running <TaskInstance: booking_ingestion.load_data manual__2023-02-17T23:25:30.795016+00:00 [running]> on host f01ad4775be8
[2023-02-17T23:25:33.962+0000] {taskinstance.py:1509} INFO - Exporting the following env vars:
AIRFLOW_CTX_DAG_OWNER=***
AIRFLOW_CTX_DAG_ID=booking_ingestion
AIRFLOW_CTX_TASK_ID=load_data
AIRFLOW_CTX_EXECUTION_DATE=2023-02-17T23:25:30.795016+00:00
AIRFLOW_CTX_TRY_NUMBER=1
AIRFLOW_CTX_DAG_RUN_ID=manual__2023-02-17T23:25:30.795016+00:00
[2023-02-17T23:25:33.966+0000] {taskinstance.py:1768} ERROR - Task failed with exception
Traceback (most recent call last):
  File "/home/airflow/.local/lib/python3.7/site-packages/airflow/operators/python.py", line 175, in execute
    return_value = self.execute_callable()
  File "/home/airflow/.local/lib/python3.7/site-packages/airflow/operators/python.py", line 192, in execute_callable
    return self.python_callable(*self.op_args, **self.op_kwargs)
  File "/opt/airflow/dags/data_ingestion_dag/main.py", line 46, in load_data
    conn = sqlite3.connect("/usr/local/airflow/db/datascience.db")
sqlite3.OperationalError: unable to open database file
[2023-02-17T23:25:33.978+0000] {taskinstance.py:1323} INFO - Marking task as FAILED. dag_id=booking_ingestion, task_id=load_data, execution_date=20230217T232530, start_date=20230217T232533, end_date=20230217T232533
[2023-02-17T23:25:33.986+0000] {standard_task_runner.py:105} ERROR - Failed to execute job 77 for task load_data (unable to open database file; 82)
[2023-02-17T23:25:34.014+0000] {local_task_job.py:208} INFO - Task exited with return code 1
[2023-02-17T23:25:34.030+0000] {taskinstance.py:2578} INFO - 0 downstream tasks scheduled from follow-on schedule check
